Workbook

Sheet Overall Summary Snapshot
B1: Reporting Date | C1: 45715 | D1: <- populate this date in the same format
D2: The below table is auto populated; do not alter any cell formula
B5: KT STATUS DASHBOARD | E5: As on | F5: =C1 -> 45715
C6: Tower Owner | D6: Overall KT Topics | E6: KT Topics | G6: Playback | I6: KT Progress (Planned vs. Actual) | J6: Overall KT Progress
E7: Planned | F7: Actual | G7: Planned | H7: Actual
B8: All Towers | D8: =SUM(D9:D16) -> 2312 | E8: =SUM(E9:E16) -> 650.5 | F8: =SUM(F9:F16) -> 595.25 | G8: =SUM(G9:G16) -> 3 | H8: =SUM(H9:H16) -> 2 | I8: =IF(F8>0,F8/E8,0) -> 0.91506533 | J8: =IF(F8>0,F8/D8,0) -> 0.25746107
B9: Corp Apps | C9: John | D9: =Detailed!D16 -> 671 | E9: =SUMIFS(Detailed!E16:BY16, Detailed!E6:BY6,">=17-Feb-2025", Detailed!E6:BY6, "<="&'Overall Summary Snapshot'!C1) -> 176 | F9: =SUM(Detailed!E17:BY17) -> 88 | G9: =SUMIFS(Detailed!E18:BY18, Detailed!E6:BY6,">=17-Feb-2025", Detailed!E6:BY6, "<="&'Overall Summary Snapshot'!C1) -> 0 | H9: =SUMIFS(Detailed!E19:BY19, Detailed!E6:BY6,">=17-Feb-2025", Detailed!E6:BY6, "<="&'Overall Summary Snapshot'!C1) -> 0 | I9: =IF(F9>0,F9/E9,0) -> 0.5 | J9: =IF(F9>0,F9/D9,0) -> 0.13114754 | K9: KT Cancelled due to Holiday(LTIM and TCS)
B10: SAP | C10: Maddy | D10: =Detailed!D22 -> 947 | E10: =SUMIFS(Detailed!E22:BY22, Detailed!E6:BY6,">=17-Feb-2025", Detailed!E6:BY6, "<="&'Overall Summary Snapshot'!C1) -> 259 | F10: =SUM(Detailed!E23:BY23) -> 283 | G10: =SUMIFS(Detailed!E24:BY24, Detailed!E6:BY6,">=17-Feb-2025", Detailed!E6:BY6, "<="&'Overall Summary Snapshot'!C1) -> 0 | H10: =SUMIFS(Detailed!E25:BY25, Detailed!E6:BY6,">=17-Feb-2025", Detailed!E6:BY6, "<="&'Overall Summary Snapshot'!C1) -> 0 | I10: =IF(F10>0,F10/E10,0) -> 1.0926641 | J10: =IF(F10>0,F10/D10,0) -> 0.29883844 | K10: Green
B11: Integration | C11: Richard | D11: =Detailed!D28 -> 154 | E11: =SUMIFS(Detailed!E28:BY28, Detailed!E6:BY6,">=17-Feb-2025", Detailed!E6:BY6, "<="&'Overall Summary Snapshot'!C1) -> 55 | F11: =SUM(Detailed!E29:BY29) -> 51 | G11: =SUMIFS(Detailed!E30:BY30, Detailed!E6:BY6,">=17-Feb-2025", Detailed!E6:BY6, "<="&'Overall Summary Snapshot'!C1) -> 2 | H11: =SUMIFS(Detailed!E31:BY31, Detailed!E6:BY6,">=17-Feb-2025", Detailed!E6:BY6, "<="&'Overall Summary Snapshot'!C1) -> 2 | I11: =IF(F11>0,F11/E11,0) -> 0.92727273 | J11: =IF(F11>0,F11/D11,0) -> 0.33116883
B12: EIT | C12: Madhav | D12: =Detailed!D34 -> 75 | E12: =SUMIFS(Detailed!E34:BY34, Detailed!E6:BY6,">=17-Feb-2025", Detailed!E6:BY6, "<="&'Overall Summary Snapshot'!C1) -> 51 | F12: =SUM(Detailed!E35:BY35) -> 39 | G12: =SUMIFS(Detailed!E36:BY36, Detailed!E6:BY6,">=17-Feb-2025", Detailed!E6:BY6, "<="&'Overall Summary Snapshot'!C1) -> 0 | H12: =SUMIFS(Detailed!E37:BY37, Detailed!E6:BY6,">=17-Feb-2025", Detailed!E6:BY6, "<="&'Overall Summary Snapshot'!C1) -> 0 | I12: =IF(F12>0,F12/E12,0) -> 0.76470588 | J12: =IF(F12>0,F12/D12,0) -> 0.52
B13: EDA | C13: Cummins | D13: =Detailed!D40 -> 392 | E13: =SUMIFS(Detailed!E40:BY40, Detailed!E6:BY6,">=17-Feb-2025", Detailed!E6:BY6, "<="&'Overall Summary Snapshot'!C1) -> 79 | F13: =SUM(Detailed!E41:BY41) -> 107 | G13: =SUMIFS(Detailed!E42:BY42, Detailed!E6:BY6,">=17-Feb-2025", Detailed!E6:BY6, "<="&'Overall Summary Snapshot'!C1) -> 0 | H13: =SUMIFS(Detailed!E43:BY43, Detailed!E6:BY6,">=17-Feb-2025", Detailed!E6:BY6, "<="&'Overall Summary Snapshot'!C1) -> 0 | I13: =IF(F13>0,F13/E13,0) -> 1.3544304 | J13: =IF(F13>0,F13/D13,0) -> 0.27295918
B14: Sharepoint | C14: Sachin | D14: =Detailed!D46 -> 34 | E14: =SUMIFS(Detailed!E46:BY46, Detailed!E6:BY6,">=17-Feb-2025", Detailed!E6:BY6, "<="&'Overall Summary Snapshot'!C1) -> 14.5 | F14: =SUM(Detailed!E47:BY47) -> 12.25 | G14: =SUMIFS(Detailed!E48:BY48, Detailed!E6:BY6,">=17-Feb-2025", Detailed!E6:BY6, "<="&'Overall Summary Snapshot'!C1) -> 0 | H14: =SUMIFS(Detailed!E49:BY49, Detailed!E6:BY6,">=17-Feb-2025", Detailed!E6:BY6, "<="&'Overall Summary Snapshot'!C1) -> 0 | I14: =IF(F14>0,F14/E14,0) -> 0.84482759 | J14: =IF(F14>0,F14/D14,0) -> 0.36029412
B15: Service Now | C15: Vinod | D15: =Detailed!D52 -> 28 | E15: =SUMIFS(Detailed!E52:BY52, Detailed!E6:BY6,">=17-Feb-2025", Detailed!E6:BY6, "<="&'Overall Summary Snapshot'!C1) -> 9 | F15: =SUM(Detailed!E53:BY53) -> 8 | G15: =SUMIFS(Detailed!E54:BY54, Detailed!E6:BY6,">=17-Feb-2025", Detailed!E6:BY6, "<="&'Overall Summary Snapshot'!C1) -> 0 | H15: =SUMIFS(Detailed!E55:BY55, Detailed!E6:BY6,">=17-Feb-2025", Detailed!E6:BY6, "<="&'Overall Summary Snapshot'!C1) -> 0 | I15: =IF(F15>0,F15/E15,0) -> 0.88888889 | J15: =IF(F15>0,F15/D15,0) -> 0.28571429
B16: LAN | C16: Prachi | D16: =Detailed!D58 -> 11 | E16: =SUMIFS(Detailed!E58:BY58, Detailed!E6:BY6,">=17-Feb-2025", Detailed!E6:BY6, "<="&'Overall Summary Snapshot'!C1) -> 7 | F16: =SUM(Detailed!E59:BY59) -> 7 | G16: =SUMIFS(Detailed!E60:BY60, Detailed!E6:BY6,">=17-Feb-2025", Detailed!E6:BY6, "<="&'Overall Summary Snapshot'!C1) -> 1 | H16: =SUMIFS(Detailed!E61:BY61, Detailed!E6:BY6,">=17-Feb-2025", Detailed!E6:BY6, "<="&'Overall Summary Snapshot'!C1) -> 0 | I16: =IF(F16>0,F16/E16,0) -> 1 | J16: =IF(F16>0,F16/D16,0) -> 0.63636364
B19: KT STATUS DASHBOARD | E19: As on | F19: =TODAY() -> 45996 | K19: =TEXT(WEEKDAY(K20),"DDD") -> Wed | L19: =TEXT(WEEKDAY(L20),"DDD") -> Thu | M19: =TEXT(WEEKDAY(M20),"DDD") -> Fri | N19: =TEXT(WEEKDAY(N20),"DDD") -> Sat | O19: =TEXT(WEEKDAY(O20),"DDD") -> Sun | P19: =TEXT(WEEKDAY(P20),"DDD") -> Mon | Q19: =TEXT(WEEKDAY(Q20),"DDD") -> Tue | R19: =TEXT(WEEKDAY(R20),"DDD") -> Wed | ... AY19: =TEXT(WEEKDAY(AY20),"DDD") -> Mon
C20: Tower Owner | D20: Overall KT Topics | E20: KT Topics | G20: Playback | I20: KT Progress (Planned vs. Actual) | J20: Overall KT Progress | K20: 45714 | L20: =K20+1 -> 45715 | M20: =L20+1 -> 45716 | N20: =M20+1 -> 45717 | O20: =N20+1 -> 45718 | P20: =O20+1 -> 45719 | Q20: =P20+1 -> 45720 | R20: =Q20+1 -> 45721 | S20: =R20+1 -> 45722 | ... AY20: =AX20+1 -> 45754
E21: Planned | F21: Actual | G21: Planned | H21: Actual | K21: Additional Comments | L21: Additional Comments | M21: Additional Comments | N21: Additional Comments | O21: Additional Comments | P21: Additional Comments | Q21: Additional Comments | R21: Additional Comments | S21: Additional Comments | T21: Additional Comments | U21: Additional Comments | V21: Additional Comments | W21: Additional Comments | X21: Additional Comments | Y21: Additional Comments | Z21: Additional Comments | AA21: Additional Comments | AB21: Additional Comments | AC21: Additional Comments | AD21: Additional Comments | AE21: Additional Comments | AF21: Additional Comments | AG21: Additional Comments | AH21: Additional Comments | AI21: Additional Comments | AJ21: Additional Comments | AK21: Additional Comments | AL21: Additional Comments | AM21: Additional Comments | AN21: Additional Comments | AO21: Additional Comments
B22: All Towers | D22: =SUM(D23:D31) -> 2945 | E22: =SUM(E23:E31) -> 2945 | F22: =SUM(F23:F31) -> 2945 | G22: =SUM(G23:G30) -> 98 | H22: =SUM(H23:H30) -> 98 | I22: =IF(F22>0,F22/E22,0) -> 1 | J22: =IF(F22>0,F22/D22,0) -> 1
B23: Corp Apps | C23: John | D23: ='Detailed New'!I8 -> 660 | E23: ='Detailed New'!I6 -> 660 | F23: ='Detailed New'!J6 -> 660 | G23: ='Detailed New'!K6 -> 36 | H23: ='Detailed New'!L6 -> 34 | I23: =IF(F23>0,F23/E23,0) -> 1 | J23: =IF(F23>0,F23/D23,0) -> 1 | K23: KT Cancelled due to Holiday( LTIM and TCS) | M23: Backlog sessions need to be covered. | P23: Backlog sessions need to be covered. | Q23: All green | R23: All green | S23: All green | T23: All green | U23: All green | V23: All green | W23: All green | X23: All green | Y23: All green | Z23: All green | AA23: All green | AB23: All green | AC23: All green | AD23: All green | AE23: All green | AF23: All green | AG23: All green | AH23: All green | AK23: All green | AL23: All green | AM23: KT completed | AN23: KT completed | AO23: KT completed
B24: SAP | C24: Maddy | D24: ='Detailed New'!N8 -> 1296 | E24: ='Detailed New'!N6 -> 1296 | F24: ='Detailed New'!O6 -> 1295 | G24: ='Detailed New'!P6 -> 18 | H24: ='Detailed New'!Q6 -> 18 | I24: =IF(F24>0,F24/E24,0) -> 0.9992284 | J24: =IF(F24>0,F24/D24,0) -> 0.9992284 | K24: Green | M24: All green | P24: All green | Q24: All green | R24: All green | S24: All green | T24: All green | U24: All green | V24: All green | W24: All green | X24: All green | Y24: All green | Z24: All green | AA24: All green | AB24: All green | AC24: All green | AD24: All green | AE24: All green | AF24: All green | AG24: All green | AH24: All green | AK24: All green | AL24: All green | AM24: All green | AN24: KT completed | AO24: KT completed
B25: Integration | C25: Richard | D25: ='Detailed New'!S8 -> 131 | E25: ='Detailed New'!S6 -> 131 | F25: ='Detailed New'!T6 -> 131 | G25: ='Detailed New'!U6 -> 6 | H25: ='Detailed New'!V6 -> 6 | I25: =IF(F25>0,F25/E25,0) -> 1 | J25: =IF(F25>0,F25/D25,0) -> 1 | K25: KCD pending fromLTIM on SFG & SSP | M25: All green | P25: All green | Q25: All green | R25: All green | S25: All green | T25: All green | U25: All green | V25: All green | W25: All green | X25: All green | Y25: All green | Z25: All green | AA25: All green | AB25: All green | AC25: All green | AD25: All green | AE25: All green | AF25: All green | AG25: All green | AH25: All green | AK25: All green | AL25: All green | AM25: All green | AN25: KT completed | AO25: KT completed
B26: EIT | C26: Madhav | D26: ='Detailed New'!X8 -> 348 | E26: ='Detailed New'!X6 -> 348 | F26: ='Detailed New'!Y6 -> 348 | G26: ='Detailed New'!Z6 -> 12 | H26: ='Detailed New'!AA6 -> 13 | I26: =IF(F26>0,F26/E26,0) -> 1 | J26: =IF(F26>0,F26/D26,0) -> 1 | M26: All green | P26: All green | Q26: All green | R26: All green | S26: All green | T26: All green | U26: All green | V26: All green | W26: All green | X26: All green | Y26: All green | Z26: All green | AA26: All green | AB26: All green | AC26: All green | AD26: All green | AE26: All green | AF26: All green | AG26: All green | AH26: All green | AK26: All green | AL26: All green | AM26: KT completed | AN26: KT completed | AO26: KT completed
B27: EDA | C27: Cummins | D27: ='Detailed New'!AC8 -> 348 | E27: ='Detailed New'!AC6 -> 348 | F27: ='Detailed New'!AD6 -> 348 | G27: ='Detailed New'!AE6 -> 8 | H27: ='Detailed New'!AF6 -> 8 | I27: =IF(F27>0,F27/E27,0) -> 1 | J27: =IF(F27>0,F27/D27,0) -> 1 | M27: All green | P27: All green | Q27: All green | R27: All green | S27: All green | T27: All green | U27: All green | V27: All green | W27: All green | X27: All green | Y27: All green | Z27: All green | AA27: All green | AB27: All green | AC27: All green | AD27: All green | AE27: All green | AF27: All green | AG27: All green | AH27: All green | AK27: All green | AL27: All green | AM27: All green | AN27: KT completed | AO27: KT completed
B28: Sharepoint | C28: Sachin | D28: ='Detailed New'!AH8 -> 35 | E28: ='Detailed New'!AH6 -> 35 | F28: ='Detailed New'!AI6 -> 35 | G28: ='Detailed New'!AJ6 -> 11 | H28: ='Detailed New'!AK6 -> 13 | I28: =IF(F28>0,F28/E28,0) -> 1 | J28: =IF(F28>0,F28/D28,0) -> 1 | M28: All green | P28: All green | Q28: All green | R28: All green | S28: All green | T28: All green | U28: All green | V28: All green | W28: All green | X28: All green | Y28: All green | Z28: All green | AA28: All green | AB28: All green | AC28: All green | AD28: All green | AE28: All green | AF28: All green | AG28: All green | AH28: All green | AK28: All green | AL28: All green | AM28: KT completed | AN28: KT completed | AO28: KT completed
B29: Service Now | C29: Vinod | D29: ='Detailed New'!AM8 -> 28 | E29: ='Detailed New'!AM6 -> 28 | F29: ='Detailed New'!AN6 -> 28 | G29: ='Detailed New'!AO6 -> 2 | H29: ='Detailed New'!AP6 -> 2 | I29: =IF(F29>0,F29/E29,0) -> 1 | J29: =IF(F29>0,F29/D29,0) -> 1 | M29: All green | P29: All green | Q29: All green | R29: All green | S29: All green | T29: All green | U29: All green | V29: All green | W29: All green | X29: All green | Y29: All green | Z29: All green | AA29: All green | AB29: All green | AC29: All green | AD29: All green | AE29: All green | AF29: All green | AG29: All green | AH29: All green | AK29: All green | AL29: All green | AM29: KT completed | AN29: KT completed | AO29: KT completed
B30: LAN | C30: Prachi | D30: ='Detailed New'!AR8 -> 11 | E30: ='Detailed New'!AR6 -> 11 | F30: ='Detailed New'!AS6 -> 12 | G30: ='Detailed New'!AT6 -> 5 | H30: ='Detailed New'!AU6 -> 4 | I30: =IF(F30>0,F30/E30,0) -> 1.0909091 | J30: =IF(F30>0,F30/D30,0) -> 1.0909091 | M30: No session planned for today | P30: All green | Q30: All green | R30: All green | S30: All green | T30: All green | U30: All green | V30: All green | W30: All green | X30: All green | Y30: All green | Z30: All green | AA30: All green | AB30: All green | AC30: All green | AD30: All green | AE30: All green | AF30: All green | AG30: All green | AH30: All green | AK30: All green | AL30: All green | AM30: KT completed | AN30: KT completed | AO30: KT completed
B31: AS400 | C31: jonny | D31: ='Detailed New'!AW8 -> 88 | E31: ='Detailed New'!AW6 -> 88 | F31: ='Detailed New'!AX6 -> 88 | G31: ='Detailed New'!AY6 -> 2 | H31: ='Detailed New'!AZ6 -> 2 | I31: =IF(F31>0,F31/E31,0) -> 1 | J31: =IF(F31>0,F31/D31,0) -> 1 | M31: Session cancelled due to unavailability of LTIM SME | P31: Session cancelled due to unavailability of LTIM SME | Q31: LTIM SME is not available for KT last week . Backlog to be covered this week. | R31: LTIM SME is not available for KT last week . Backlog to be covered this week. | S31: All green | T31: All green | U31: All green | V31: All green | W31: All green | X31: All green | Y31: All green | Z31: All green | AA31: All green | AB31: All green | AC31: All green | AD31: All green | AE31: All green | AF31: All green | AG31: All green | AH31: All green | AK31: All green | AL31: All green | AM31: KT completed | AN31: KT completed | AO31: KT completed
C34: Tower Owner | D34: Overall KT Topics | E34: KT Topics | G34: Playback | I34: KT Progress (Planned vs. Actual) | J34: Overall KT Progress | K34: 45714
E35: Planned | F35: Actual | G35: Planned | H35: Actual | K35: Additional Comments
B36: All Towers | D36: 2340 | E36: 539.25 | F36: 512.25 | G36: 3 | H36: 2 | I36: 0.94993046 | J36: 0.21891026

Sheet Detailed
A4: PHINIA KT DASHBOARD
D5: Column Auto Populate | E5: M | F5: T | G5: W | H5: T | I5: T | J5: S | K5: S | L5: M | M5: T | N5: W | O5: T | P5: F | Q5: S | R5: S | S5: M | T5: T | U5: W | V5: T | W5: F | X5: S | Y5: S | Z5: M | AA5: T | AB5: W | AC5: T | AD5: F | AE5: S | AF5: S | AG5: M | AH5: T | AI5: W | AJ5: T | AK5: F | AL5: S | AM5: S | AN5: M | AO5: T | AP5: W | AQ5: T | AR5: F | AS5: S | AT5: S | AU5: M | AV5: T | AW5: W | AX5: T | AY5: F | AZ5: S | BA5: S | BB5: M | BC5: T | BD5: W | BE5: T | BF5: F | BG5: S | BH5: S | BI5: M | BJ5: T | BK5: W | BL5: T | BM5: F | BN5: S | BO5: S | BP5: M | BQ5: T | BR5: W | BS5: T | BT5: F | BU5: S | BV5: S | BW5: M | BX5: T | BY5: W
A6: Towers | B6: KT Owner | C6: KT Topics | D6: Summary | E6: 45705 | F6: =E6+1 -> 45706 | G6: =F6+1 -> 45707 | H6: =G6+1 -> 45708 | I6: =H6+1 -> 45709 | J6: =I6+1 -> 45710 | K6: =J6+1 -> 45711 | L6: =K6+1 -> 45712 | M6: =L6+1 -> 45713 | ... BY6: =BX6+1 -> 45777
I7: F
A8: All Towers | C8: Overall | D8: =D10/D9 -> 0.25746107 | E8: =IF(E9=0,0,E10/E9) -> 0.98947368 | F8: =IF(F9=0,0,F10/F9) -> 1.0666667 | G8: =IF(G9=0,0,G10/G9) -> 2.1016949 | H8: =IF(H9=0,0,H10/H9) -> 1.88 | I8: =IF(I9=0,0,I10/I9) -> 0.95275591 | J8: =IF(J9=0,0,J10/J9) -> 1 | K8: =IF(K9=0,0,K10/K9) -> 1 | L8: =IF(L9=0,0,L10/L9) -> 0.9751693 | ... BY8: =IF(BY9=0,0,BY10/BY9) -> 0
C9: Planned | D9: =SUM(D16,D22,D28,D34,D40,D46,D52,D58) -> 2312 | E9: =SUM(E16,E22,E28,E34,E40,E46,E52,E58) -> 47.5 | F9: =SUM(F16,F22,F28,F34,F40,F46,F52,F58) -> 22.5 | G9: =SUM(G16,G22,G28,G34,G40,G46,G52,G58) -> 29.5 | H9: =SUM(H16,H22,H28,H34,H40,H46,H52,H58) -> 18.75 | I9: =SUM(I16,I22,I28,I34,I40,I46,I52,I58) -> 31.75 | J9: =SUM(J16,J22,J28,J34,J40,J46,J52,J58) -> 4 | K9: =SUM(K16,K22,K28,K34,K40,K46,K52,K58) -> 4 | ... BY9: =SUM(BY16,BY22,BY28,BY34,BY40,BY46,BY52,BY58) -> 0
C10: Actual | D10: =SUM(D17,D23,D29,D35,D41,D47,D53,D59) -> 595.25 | E10: =SUM(E17,E23,E29,E35,E41,E47,E53,E59) -> 47 | F10: =SUM(F17,F23,F29,F35,F41,F47,F53,F59) -> 24 | G10: =SUM(G17,G23,G29,G35,G41,G47,G53,G59) -> 62 | H10: =SUM(H17,H23,H29,H35,H41,H47,H53,H59) -> 35.25 | I10: =SUM(I17,I23,I29,I35,I41,I47,I53,I59) -> 30.25 | J10: =SUM(J17,J23,J29,J35,J41,J47,J53,J59) -> 4 | K10: =SUM(K17,K23,K29,K35,K41,K47,K53,K59) -> 4 | ... BY10: =SUM(BY17,BY23,BY29,BY35,BY41,BY47,BY53,BY59) -> 0
C11: Playback (P) | D11: =SUM(D18,D24,D30,D36,D42,D48,D54,D60) -> 35 | E11: =SUM(E18,E24,E30,E36,E42,E48,E54,E60) -> 0 | F11: =SUM(F18,F24,F30,F36,F42,F48,F54,F60) -> 0 | G11: =SUM(G18,G24,G30,G36,G42,G48,G54,G60) -> 0 | H11: =SUM(H18,H24,H30,H36,H42,H48,H54,H60) -> 1 | I11: =SUM(I18,I24,I30,I36,I42,I48,I54,I60) -> 1 | J11: =SUM(J18,J24,J30,J36,J42,J48,J54,J60) -> 0 | K11: =SUM(K18,K24,K30,K36,K42,K48,K54,K60) -> 0 | ... BY11: =SUM(BY18,BY24,BY30,BY36,BY42,BY48,BY54,BY60) -> 0
C12: Playback (A) | D12: =SUM(D19,D25,D31,D37,D43,D49,D55,D61) -> 2 | E12: =SUM(E19,E25,E31,E37,E43,E49,E55,E61) -> 0 | F12: =SUM(F19,F25,F31,F37,F43,F49,F55,F61) -> 0 | G12: =SUM(G19,G25,G31,G37,G43,G49,G55,G61) -> 0 | H12: =SUM(H19,H25,H31,H37,H43,H49,H55,H61) -> 1 | I12: =SUM(I19,I25,I31,I37,I43,I49,I55,I61) -> 0 | J12: =SUM(J19,J25,J31,J37,J43,J49,J55,J61) -> 0 | K12: =SUM(K19,K25,K31,K37,K43,K49,K55,K61) -> 0 | ... BY12: =SUM(BY19,BY25,BY31,BY37,BY43,BY49,BY55,BY61) -> 0
C13: Notes
A14: TOWER LEVEL DASHBOARD
A15: Corp Apps | B15: Vijit | C15: Overall
A16: KT Plnd Till Yday | B16: =SUMIF($E$6:$BY$6,"<"&TODAY(),E16:BY16) -> 671 | C16: Planned | D16: =SUM(E16:BY16) -> 671 | E16: 13 | F16: 0 | G16: 12 | H16: 6 | I16: 13 | L16: 33 | M16: 33 | N16: 33 | O16: 33 | P16: 33 | S16: 44 | T16: 44 | U16: 44 | V16: 44 | W16: 44 | Z16: 33 | AA16: 33 | AB16: 22 | AC16: 22 | AD16: 22 | AG16: 11 | AH16: 11 | AI16: 11 | AJ16: 11 | AK16: 11 | AN16: 11 | AO16: 11 | AP16: 11 | AQ16: 11 | AR16: 11
A17: KT Act till Yday | B17: =SUMIF($E$6:$BY$6,"<"&TODAY(),E17:BY17) -> 88 | C17: Actual | D17: =SUM(E17:BY17) -> 88 | E17: 13 | F17: 0 | G17: 12 | H17: 6 | I17: 13 | L17: 27 | M17: 17 | N17: 0
A18: PlayBack Plnd | B18: =SUMIF($E$6:$BY$6,"<"&TODAY(),E18:BY18) -> 0 | C18: Playback (P) | D18: =SUM(E18:BY18) -> 0
A19: PlayBack Act | B19: =SUMIF($E$6:$BY$6,"<"&TODAY(),E19:BY19) -> 0 | C19: Playback (A) | D19: =SUM(E19:BY19) -> 0
C20: Notes | L20: Balance KT topic will be covered in the next session as planned. | M20: Balance KT topic will be covered in the next session. One of resource is OOO from TCS till 27 due to which KT topic will be covered in next session | N20: Due to Holiday,associates are not available
A21: SAP | B21: Sachin | C21: Overall
A22: KT Plnd Till Yday | B22: =SUMIF($E$6:$BY$6,"<"&TODAY(),E22:BY22) -> 947 | C22: Planned | D22: =SUM(E22:BY22) -> 947 | E22: 0 | F22: 0 | G22: 0 | H22: 0 | I22: 0 | J22: 0 | K22: 0 | L22: 57 | M22: 57 | N22: 73 | O22: 72 | P22: 21 | S22: 69 | T22: 68 | U22: 21 | V22: 17 | W22: 11 | Z22: 16 | AA22: 31 | AB22: 34 | AC22: 45 | AD22: 17 | AG22: 23 | AH22: 32 | AI22: 22 | AJ22: 17 | AK22: 56 | AN22: 28 | AO22: 27 | AP22: 31 | AQ22: 57 | AR22: 31 | AU22: 14
A23: KT Act till Yday | B23: =SUMIF($E$6:$BY$6,"<"&TODAY(),E23:BY23) -> 283 | C23: Actual | D23: =SUM(E23:BY23) -> 283 | L23: 57 | M23: 64 | N23: 64 | O23: 98
A24: PlayBack Plnd | B24: =SUMIF($E$6:$BY$6,"<"&TODAY(),E24:BY24) -> 5 | C24: Playback (P) | D24: =SUM(E24:BY24) -> 5 | I24: 0 | P24: 1 | S24: 1 | Z24: 1 | AG24: 1 | AN24: 1
A25: PlayBack Act | B25: =SUMIF($E$6:$BY$6,"<"&TODAY(),E25:BY25) -> 0 | C25: Playback (A) | D25: =SUM(E25:BY25) -> 0 | I25: 0 | P25: 0
C26: Notes | M26: 3 additional OTC topics and 4 addtional MFG topics are covered today | N26: MFG and Security sessions are not happening today due to holiday - 17 topics, 64 topics covered today which includes 11 additional topics of OTC | O26: 3 Security topics left 2 OTC additional topics 13 PTP topics left will be covered under WM topic 33 MFG additional topcis covered of 3rd and 4th March | P26: MFG playback is planned | S26: Security playback is planned
A27: Integration | B27: Harshad | C27: Overall
A28: KT Plnd Till Yday | B28: =SUMIF($E$6:$BY$6,"<"&TODAY(),E28:BY28) -> 154 | C28: Planned | D28: =SUM(E28:BY28) -> 154 | E28: 6 | F28: 6 | G28: 7 | H28: 6 | I28: 6 | L28: 8 | M28: 8 | N28: 4 | O28: 4 | P28: 4 | S28: 6 | T28: 5 | U28: 7 | V28: 9 | W28: 7 | Z28: 4 | AA28: 2 | AB28: 3 | AC28: 2 | AD28: 1 | AG28: 3 | AH28: 3 | AI28: 2 | AJ28: 2 | AK28: 3 | AN28: 3 | AO28: 3 | AP28: 5 | AQ28: 3 | AR28: 6 | AU28: 16
A29: KT Act till Yday | B29: =SUMIF($E$6:$BY$6,"<"&TODAY(),E29:BY29) -> 51 | C29: Actual | D29: =SUM(E29:BY29) -> 51 | E29: 6 | F29: 6 | G29: 7 | H29: 6 | I29: 6 | L29: 8 | M29: 8 | N29: 4
A30: PlayBack Plnd | B30: =SUMIF($E$6:$BY$6,"<"&TODAY(),E30:BY30) -> 5 | C30: Playback (P) | D30: =SUM(E30:BY30) -> 5 | H30: 1 | M30: 1 | T30: 1 | W30: 1 | AR30: 1
A31: PlayBack Act | B31: =SUMIF($E$6:$BY$6,"<"&TODAY(),E31:BY31) -> 2 | C31: Playback (A) | D31: =SUM(E31:BY31) -> 2 | H31: 1 | M31: 1
C32: Notes | H32: LTIM yet to prepare KCD docs. Hence only 6 covered out of 11 | I32: 2 topics (KCD signoff of SFG) of 20th Feb is yet to be completed. Responsible LTIM. | L32: 2 topics (KCD signoff of SFG) of 20th Feb is yet to be completed. Responsible LTIM. | M32: 2 topics (KCD signoff of SFG) of 20th Feb is yet to be completed. 5 topics (KCD & signoff of SSP) of 25th Feb is yet to be Responsible LTIM. | N32: KCD Signoff pending from LTIM on SFG.KCD doc yet to receive for SSP from LTIM.
A33: EIT | B33: Chendra | C33: Overall
A34: KT Plnd Till Yday | B34: =SUMIF($E$6:$BY$6,"<"&TODAY(),E34:BY34) -> 75 | C34: Planned | D34: =SUM(E34:BY34) -> 75 | E34: 0 | F34: 0 | G34: 0 | H34: 3 | I34: 4 | J34: 4 | K34: 4 | L34: 4 | M34: =4+1+4 -> 9 | N34: =4+4+3 -> 11 | O34: =4+4+4 -> 12 | P34: =4+4+4 -> 12 | Q34: =4+5+3 -> 12
A35: KT Act till Yday | B35: =SUMIF($E$6:$BY$6,"<"&TODAY(),E35:BY35) -> 39 | C35: Actual | D35: =SUM(E35:BY35) -> 39 | H35: 3 | I35: 4 | J35: 4 | K35: 4 | L35: 4 | M35: 9 | N35: 11
A36: PlayBack Plnd | B36: =SUMIF($E$6:$BY$6,"<"&TODAY(),E36:BY36) -> 0 | C36: Playback (P) | D36: =SUM(E36:BY36) -> 0 | H36: 0 | I36: 0 | J36: 0 | K36: 0 | L36: 0 | M36: 0
A37: PlayBack Act | B37: =SUMIF($E$6:$BY$6,"<"&TODAY(),E37:BY37) -> 0 | C37: Playback (A) | D37: =SUM(E37:BY37) -> 0 | H37: 0 | I37: 0 | J37: 0 | K37: 0 | L37: 0 | M37: 0
C38: Notes
A39: EDA | B39: Ajay | C39: Overall
A40: KT Plnd Till Yday | B40: =SUMIF($E$6:$BY$6,"<"&TODAY(),E40:BY40) -> 392 | C40: Planned | D40: =SUM(E40:BY40) -> 392 | E40: 21 | F40: 15 | G40: 7 | H40: 0 | I40: 7 | L40: 6 | M40: 8 | N40: 8 | O40: 7 | P40: 10 | S40: 39 | T40: 12 | U40: 10 | V40: 8 | W40: 13 | Z40: 20 | AA40: 13 | AB40: 12 | AC40: 11 | AD40: 8 | AG40: 11 | AH40: 13 | AI40: 32 | AJ40: 25 | AK40: =16+8 -> 24 | AN40: =11+6 -> 17 | AO40: 5 | AP40: 2 | AU40: 28
A41: KT Act till Yday | B41: =SUMIF($E$6:$BY$6,"<"&TODAY(),E41:BY41) -> 107 | C41: Actual | D41: =SUM(E41:BY41) -> 107 | E41: 21 | F41: 15 | G41: =24+15 -> 39 | H41: 16 | I41: 4 | L41: 10 | M41: 2
A42: PlayBack Plnd | B42: =SUMIF($E$6:$BY$6,"<"&TODAY(),E42:BY42) -> 8 | C42: Playback (P) | D42: =SUM(E42:BY42) -> 8 | AN42: =4+2 -> 6 | AO42: 1 | AP42: 1
A43: PlayBack Act | B43: =SUMIF($E$6:$BY$6,"<"&TODAY(),E43:BY43) -> 0 | C43: Playback (A) | D43: =SUM(E43:BY43) -> 0 | I43: 0
...

Sheet Detailed New-backup
D3: All Tower Combined Status | I3: Corp Apps: Vijith | N3: SAP: Sachin | S3: Integration: Harshad | X3: EIT: Chendra | AC3: EDA: Ajay | AH3: SharePoint: Sandeep | AM3: SNOW: Dilip | AR3: LAN: Neel | AW3: AS400: Naga | BB3: SIAM :
I4: KT (P) Till today | J4: KT (A) Till today | K4: PlayBack (P) | L4: PlayBack (A) | M4: KT till today % | N4: KT (P) Till today | O4: KT (A) Till today | P4: PlayBack (P) | Q4: PlayBack (A) | R4: KT till today % | S4: KT (P) Till today | T4: KT (A) Till today | U4: PlayBack (P) | V4: PlayBack (A) | W4: KT till today % | X4: KT (P) Till today | Y4: KT (A) Till today | Z4: PlayBack (P) | AA4: PlayBack (A) | AB4: KT till today % | AC4: KT (P) Till today | AD4: KT (A) Till today | AE4: PlayBack (P) | AF4: PlayBack (A) | AG4: KT till today % | AH4: KT (P) Till today | AI4: KT (A) Till today | AJ4: PlayBack (P) | AK4: PlayBack (A) | AL4: KT till today % | AM4: KT (P) Till today | AN4: KT (A) Till today | AO4: PlayBack (P) | AP4: PlayBack (A) | AQ4: KT till today % | AR4: KT (P) Till today | AS4: KT (A) Till today | AT4: PlayBack (P) | AU4: PlayBack (A) | AV4: KT till today % | AW4: KT (P) Till today | AX4: KT (A) Till today | AY4: PlayBack (P) | AZ4: PlayBack (A) | BA4: KT till today % | BB4: KT (P) Till today | BC4: KT (A) Till today | BD4: PlayBack (P) | BE4: PlayBack (A) | BF4: KT till today %
I5: =SUMIF($C$8:$C$70,"<"&"="&TODAY(),I8:I70) -> 671 | J5: =SUMIF($C$8:$C$70,"<"&"="&TODAY(),J8:J70) -> 385 | K5: =SUMIF($C$8:$C$70,"<"&"="&TODAY(),K8:K70) -> 2 | L5: =SUMIF($C$8:$C$70,"<"&"="&TODAY(),L8:L70) -> 2 | M5: =J5/I5 -> 0.57377049 | N5: =SUMIF($C$8:$C$70,"<"&"="&TODAY(),N8:N70) -> 1323 | O5: =SUMIF($C$8:$C$70,"<"&"="&TODAY(),O8:O70) -> 643 | P5: =SUMIF($C$8:$C$70,"<"&"="&TODAY(),P8:P70) -> 9 | Q5: =SUMIF($C$8:$C$70,"<"&"="&TODAY(),Q8:Q70) -> 2 | R5: =O5/N5 -> 0.48601663 | S5: =SUMIF($C$8:$C$70,"<"&"="&TODAY(),S8:S70) -> 154 | T5: =SUMIF($C$8:$C$70,"<"&"="&TODAY(),T8:T70) -> 86 | U5: =SUMIF($C$8:$C$70,"<"&"="&TODAY(),U8:U70) -> 5 | V5: =SUMIF($C$8:$C$70,"<"&"="&TODAY(),V8:V70) -> 3 | W5: =T5/S5 -> 0.55844156 | X5: =SUMIF($C$8:$C$70,"<"&"="&TODAY(),X8:X70) -> 94 | Y5: =SUMIF($C$8:$C$70,"<"&"="&TODAY(),Y8:Y70) -> 93 | Z5: =SUMIF($C$8:$C$70,"<"&"="&TODAY(),Z8:Z70) -> 1 | AA5: =SUMIF($C$8:$C$70,"<"&"="&TODAY(),AA8:AA70) -> 1 | AB5: =Y5/X5 -> 0.9893617 | AC5: =SUMIF($C$8:$C$70,"<"&"="&TODAY(),AC8:AC70) -> 392 | AD5: =SUMIF($C$8:$C$70,"<"&"="&TODAY(),AD8:AD70) -> 180 | AE5: =SUMIF($C$8:$C$70,"<"&"="&TODAY(),AE8:AE70) -> 8 | AF5: =SUMIF($C$8:$C$70,"<"&"="&TODAY(),AF8:AF70) -> 3 | AG5: =AD5/AC5 -> 0.45918367 | AH5: =SUMIF($C$8:$C$70,"<"&"="&TODAY(),AH8:AH70) -> 34 | AI5: =SUMIF($C$8:$C$70,"<"&"="&TODAY(),AI8:AI70) -> 24.27 | AJ5: =SUMIF($C$8:$C$70,"<"&"="&TODAY(),AJ8:AJ70) -> 11 | AK5: =SUMIF($C$8:$C$70,"<"&"="&TODAY(),AK8:AK70) -> 1 | AL5: =AI5/AH5 -> 0.71382353 | AM5: =SUMIF($C$8:$C$70,"<"&"="&TODAY(),AM8:AM70) -> 28 | AN5: =SUMIF($C$8:$C$70,"<"&"="&TODAY(),AN8:AN70) -> 11.5 | AO5: =SUMIF($C$8:$C$70,"<"&"="&TODAY(),AO8:AO70) -> 1 | AP5: =SUMIF($C$8:$C$70,"<"&"="&TODAY(),AP8:AP70) -> 0 | AQ5: =AN5/AM5 -> 0.41071429 | AR5: =SUMIF($C$8:$C$70,"<"&"="&TODAY(),AR8:AR70) -> 11 | AS5: =SUMIF($C$8:$C$70,"<"&"="&TODAY(),AS8:AS70) -> 11 | AT5: =SUMIF($C$8:$C$70,"<"&"="&TODAY(),AT8:AT70) -> 5 | AU5: =SUMIF($C$8:$C$70,"<"&"="&TODAY(),AU8:AU70) -> 1 | AV5: =AS5/AR5 -> 1 | AW5: =SUMIF($C$8:$C$70,"<"&"="&TODAY(),AW8:AW70) -> 78 | AX5: =SUMIF($C$8:$C$70,"<"&"="&TODAY(),AX8:AX70) -> 27 | AY5: =SUMIF($C$8:$C$70,"<"&"="&TODAY(),AY8:AY70) -> 2 | AZ5: =SUMIF($C$8:$C$70,"<"&"="&TODAY(),AZ8:AZ70) -> 0 | BA5: =AX5/AW5 -> 0.34615385 | BB5: =SUMIF($C$8:$C$70,"<"&"="&TODAY(),BB8:BB70) -> 15 | BC5: =SUMIF($C$8:$C$70,"<"&"="&TODAY(),BC8:BC70) -> 10 | BD5: =SUMIF($C$8:$C$70,"<"&"="&TODAY(),BD8:BD70) -> 2 | BE5: =SUMIF($C$8:$C$70,"<"&"="&TODAY(),BE8:BE70) -> 2 | BF5: =BC5/BB5 -> 0.66666667
C6: KT Topics | D6: Overall | E6: Planned | F6: Actual | G6: Playback (P) | H6: Playback (A) | I6: Planned | J6: Actual | K6: Playback (P) | L6: Playback (A) | M6: Notes | N6: Planned | O6: Actual | P6: Playback (P) | Q6: Playback (A) | R6: Notes | S6: Planned | T6: Actual | U6: Playback (P) | V6: Playback (A) | W6: Notes | X6: Planned | Y6: Actual | Z6: Playback (P) | AA6: Playback (A) | AB6: Notes | AC6: Planned | AD6: Actual | AE6: Playback (P) | AF6: Playback (A) | AG6: Notes | AH6: Planned | AI6: Actual | AJ6: Playback (P) | AK6: Playback (A) | AL6: Notes | AM6: Planned | AN6: Actual | AO6: Playback (P) | AP6: Playback (A) | AQ6: Notes | AR6: Planned | AS6: Actual | AT6: Playback (P) | AU6: Playback (A) | AV6: Notes | AW6: Planned | AX6: Actual | AY6: Playback (P) | AZ6: Playback (A) | BA6: Notes | BB6: Planned | BC6: Actual | BD6: Playback (P) | BE6: Playback (A) | BF6: Notes
C7: Overall Summary | D7: =IF(E7=0,0,F7/E7) -> 0.52451346 | E7: =SUM(I7,N7,S7,X7,AC7,AH7,AM7,AR7,AW7) -> 2785 | F7: =SUM(J7,O7,T7,Y7,AD7,AI7,AN7,AS7,AX7) -> 1460.77 | G7: =SUM(K7,P7,U7,Z7,AE7,AJ7,AO7,AT7,AY7) -> 44 | H7: =SUM(L7,Q7,V7,AA7,AF7,AK7,AP7,AU7,BA7) -> 13 | I7: =SUM(I8:I12,I14:I18,I20:I24,I26:I30,I32:I36,I38:I42,I44:I48,I50:I54,I56:I60,I62:I66,I68:I70) -> 671 | J7: =SUM(J8:J12,J14:J18,J20:J24,J26:J30,J32:J36,J38:J42,J44:J48,J50:J54,J56:J60,J62:J66,J68:J70) -> 385 | K7: =SUM(K8:K12,K14:K18,K20:K24,K26:K30,K32:K36,K38:K42,K44:K48,K50:K54,K56:K60,K62:K66,K68:K70) -> 2 | L7: =SUM(L8:L12,L14:L18,L20:L24,L26:L30,L32:L36,L38:L42,L44:L48,L50:L54,L56:L60,L62:L66,L68:L70) -> 2 | N7: =SUM(N8:N12,N14:N18,N20:N24,N26:N30,N32:N36,N38:N42,N44:N48,N50:N54,N56:N60,N62:N66,N68:N70) -> 1323 | O7: =SUM(O8:O12,O14:O18,O20:O24,O26:O30,O32:O36,O38:O42,O44:O48,O50:O54,O56:O60,O62:O66,O68:O70) -> 643 | P7: =SUM(P8:P12,P14:P18,P20:P24,P26:P30,P32:P36,P38:P42,P44:P48,P50:P54,P56:P60,P62:P66,P68:P70) -> 9 | Q7: =SUM(Q8:Q12,Q14:Q18,Q20:Q24,Q26:Q30,Q32:Q36,Q38:Q42,Q44:Q48,Q50:Q54,Q56:Q60,Q62:Q66,Q68:Q70) -> 2 | S7: =SUM(S8:S12,S14:S18,S20:S24,S26:S30,S32:S36,S38:S42,S44:S48,S50:S54,S56:S60,S62:S66,S68:S70) -> 154 | T7: =SUM(T8:T12,T14:T18,T20:T24,T26:T30,T32:T36,T38:T42,T44:T48,T50:T54,T56:T60,T62:T66,T68:T70) -> 86 | U7: =SUM(U8:U12,U14:U18,U20:U24,U26:U30,U32:U36,U38:U42,U44:U48,U50:U54,U56:U60,U62:U66,U68:U70) -> 5 | V7: =SUM(V8:V12,V14:V18,V20:V24,V26:V30,V32:V36,V38:V42,V44:V48,V50:V54,V56:V60,V62:V66,V68:V70) -> 3 | X7: =SUM(X8:X12,X14:X18,X20:X24,X26:X30,X32:X36,X38:X42,X44:X48,X50:X54,X56:X60,X62:X66,X68:X70) -> 94 | Y7: =SUM(Y8:Y12,Y14:Y18,Y20:Y24,Y26:Y30,Y32:Y36,Y38:Y42,Y44:Y48,Y50:Y54,Y56:Y60,Y62:Y66,Y68:Y70) -> 93 | Z7: =SUM(Z8:Z12,Z14:Z18,Z20:Z24,Z26:Z30,Z32:Z36,Z38:Z42,Z44:Z48,Z50:Z54,Z56:Z60,Z62:Z66,Z68:Z70) -> 1 | AA7: =SUM(AA8:AA12,AA14:AA18,AA20:AA24,AA26:AA30,AA32:AA36,AA38:AA42,AA44:AA48,AA50:AA54,AA56:AA60,AA62:AA66,AA68:AA70) -> 1 | AC7: =SUM(AC8:AC12,AC14:AC18,AC20:AC24,AC26:AC30,AC32:AC36,AC38:AC42,AC44:AC48,AC50:AC54,AC56:AC60,AC62:AC66,AC68:AC70) -> 392 | AD7: =SUM(AD8:AD12,AD14:AD18,AD20:AD24,AD26:AD30,AD32:AD36,AD38:AD42,AD44:AD48,AD50:AD54,AD56:AD60,AD62:AD66,AD68:AD70) -> 180 | AE7: =SUM(AE8:AE12,AE14:AE18,AE20:AE24,AE26:AE30,AE32:AE36,AE38:AE42,AE44:AE48,AE50:AE54,AE56:AE60,AE62:AE66,AE68:AE70) -> 8 | AF7: =SUM(AF8:AF12,AF14:AF18,AF20:AF24,AF26:AF30,AF32:AF36,AF38:AF42,AF44:AF48,AF50:AF54,AF56:AF60,AF62:AF66,AF68:AF70) -> 3 | AH7: =SUM(AH8:AH12,AH14:AH18,AH20:AH24,AH26:AH30,AH32:AH36,AH38:AH42,AH44:AH48,AH50:AH54,AH56:AH60,AH62:AH66,AH68:AH70) -> 34 | AI7: =SUM(AI8:AI12,AI14:AI18,AI20:AI24,AI26:AI30,AI32:AI36,AI38:AI42,AI44:AI48,AI50:AI54,AI56:AI60,AI62:AI66,AI68:AI70) -> 24.27 | AJ7: =SUM(AJ8:AJ12,AJ14:AJ18,AJ20:AJ24,AJ26:AJ30,AJ32:AJ36,AJ38:AJ42,AJ44:AJ48,AJ50:AJ54,AJ56:AJ60,AJ62:AJ66,AJ68:AJ70) -> 11 | AK7: =SUM(AK8:AK12,AK14:AK18,AK20:AK24,AK26:AK30,AK32:AK36,AK38:AK42,AK44:AK48,AK50:AK54,AK56:AK60,AK62:AK66,AK68:AK70) -> 1 | AM7: =SUM(AM8:AM12,AM14:AM18,AM20:AM24,AM26:AM30,AM32:AM36,AM38:AM42,AM44:AM48,AM50:AM54,AM56:AM60,AM62:AM66,AM68:AM70) -> 28 | AN7: =SUM(AN8:AN12,AN14:AN18,AN20:AN24,AN26:AN30,AN32:AN36,AN38:AN42,AN44:AN48,AN50:AN54,AN56:AN60,AN62:AN66,AN68:AN70) -> 11.5 | AO7: =SUM(AO8:AO12,AO14:AO18,AO20:AO24,AO26:AO30,AO32:AO36,AO38:AO42,AO44:AO48,AO50:AO54,AO56:AO60,AO62:AO66,AO68:AO70) -> 1 | AP7: =SUM(AP8:AP12,AP14:AP18,AP20:AP24,AP26:AP30,AP32:AP36,AP38:AP42,AP44:AP48,AP50:AP54,AP56:AP60,AP62:AP66,AP68:AP70) -> 0 | AR7: =SUM(AR8:AR12,AR14:AR18,AR20:AR24,AR26:AR30,AR32:AR36,AR38:AR42,AR44:AR48,AR50:AR54,AR56:AR60,AR62:AR66,AR68:AR70) -> 11 | AS7: =SUM(AS8:AS12,AS14:AS18,AS20:AS24,AS26:AS30,AS32:AS36,AS38:AS42,AS44:AS48,AS50:AS54,AS56:AS60,AS62:AS66,AS68:AS70) -> 11 | AT7: =SUM(AT8:AT12,AT14:AT18,AT20:AT24,AT26:AT30,AT32:AT36,AT38:AT42,AT44:AT48,AT50:AT54,AT56:AT60,AT62:AT66,AT68:AT70) -> 5 | AU7: =SUM(AU8:AU12,AU14:AU18,AU20:AU24,AU26:AU30,AU32:AU36,AU38:AU42,AU44:AU48,AU50:AU54,AU56:AU60,AU62:AU66,AU68:AU70) -> 1 | AW7: =SUM(AW8:AW12,AW14:AW18,AW20:AW24,AW26:AW30,AW32:AW36,AW38:AW42,AW44:AW48,AW50:AW54,AW56:AW60,AW62:AW66,AW68:AW70) -> 78 | AX7: =SUM(AX8:AX12,AX14:AX18,AX20:AX24,AX26:AX30,AX32:AX36,AX38:AX42,AX44:AX48,AX50:AX54,AX56:AX60,AX62:AX66,AX68:AX70) -> 27 | AY7: =SUM(AY8:AY12,AY14:AY18,AY20:AY24,AY26:AY30,AY32:AY36,AY38:AY42,AY44:AY48,AY50:AY54,AY56:AY60,AY62:AY66,AY68:AY70) -> 2 | AZ7: =SUM(AZ8:AZ12,AZ14:AZ18,AZ20:AZ24,AZ26:AZ30,AZ32:AZ36,AZ38:AZ42,AZ44:AZ48,AZ50:AZ54,AZ56:AZ60,AZ62:AZ66,AZ68:AZ70) -> 0 | BB7: =SUM(BB8:BB12,BB14:BB18,BB20:BB24,BB26:BB30,BB32:BB36,BB38:BB42,BB44:BB48,BB50:BB54,BB56:BB60,BB62:BB66,BB68:BB70) -> 15 | BC7: =SUM(BC8:BC12,BC14:BC18,BC20:BC24,BC26:BC30,BC32:BC36,BC38:BC42,BC44:BC48,BC50:BC54,BC56:BC60,BC62:BC66,BC68:BC70) -> 10 | BD7: =SUM(BD8:BD12,BD14:BD18,BD20:BD24,BD26:BD30,BD32:BD36,BD38:BD42,BD44:BD48,BD50:BD54,BD56:BD60,BD62:BD66,BD68:BD70) -> 2 | BE7: =SUM(BE8:BE12,BE14:BE18,BE20:BE24,BE26:BE30,BE32:BE36,BE38:BE42,BE44:BE48,BE50:BE54,BE56:BE60,BE62:BE66,BE68:BE70) -> 2
B8: M | C8: 45705 | D8: =IF(E8=0,0,F8/E8) -> 0.99029126 | E8: =SUM(I8,N8,S8,X8,AC8,AH8,AM8,AR8,AW8) -> 51.5 | F8: =SUM(J8,O8,T8,Y8,AD8,AI8,AN8,AS8,AX8) -> 51 | G8: =SUM(K8,P8,U8,Z8,AE8,AJ8,AO8,AT8,AY8) -> 0 | H8: =SUM(L8,Q8,V8,AA8,AF8,AK8,AP8,AU8,BA8) -> 0 | I8: 13 | J8: 13 | N8: 0 | S8: 6 | T8: 6 | X8: 0 | AC8: 21 | AD8: 21 | AH8: 0.5 | AI8: 1 | AM8: 6 | AN8: 5 | AR8: 1 | AS8: 1 | AW8: 4 | AX8: 4
B9: T | C9: =C8+1 -> 45706 | D9: =IF(E9=0,0,F9/E9) -> 1.0566038 | E9: =SUM(I9,N9,S9,X9,AC9,AH9,AM9,AR9,AW9) -> 26.5 | F9: =SUM(J9,O9,T9,Y9,AD9,AI9,AN9,AS9,AX9) -> 28 | G9: =SUM(K9,P9,U9,Z9,AE9,AJ9,AO9,AT9,AY9) -> 0 | H9: =SUM(L9,Q9,V9,AA9,AF9,AK9,AP9,AU9,BA9) -> 0 | I9: 0 | J9: 0 | N9: 0 | S9: 6 | T9: 6 | X9: 0 | AC9: 15 | AD9: 15 | AH9: 0.5 | AI9: 1 | AM9: 0 | AN9: 1 | AR9: 1 | AS9: 1 | AW9: 4 | AX9: 4
B10: W | C10: =C9+1 -> 45707 | D10: =IF(E10=0,0,F10/E10) -> 2.031746 | E10: =SUM(I10,N10,S10,X10,AC10,AH10,AM10,AR10,AW10) -> 31.5 | F10: =SUM(J10,O10,T10,Y10,AD10,AI10,AN10,AS10,AX10) -> 64 | G10: =SUM(K10,P10,U10,Z10,AE10,AJ10,AO10,AT10,AY10) -> 0 | H10: =SUM(L10,Q10,V10,AA10,AF10,AK10,AP10,AU10,BA10) -> 0 | I10: 12 | J10: 12 | N10: 0 | S10: 7 | T10: 7 | X10: 0 | AC10: 7 | AD10: =24+15 -> 39 | AH10: 1.5 | AI10: 2 | AM10: 1 | AN10: 1 | AR10: 1 | AS10: 1 | AW10: 2 | AX10: 2 | BB10: 2 | BC10: 2 | BF10: Incident & Complaints Mgmt Completed
B11: T | C11: =C10+1 -> 45708 | D11: =IF(E11=0,0,F11/E11) -> 1.7586207 | E11: =SUM(I11,N11,S11,X11,AC11,AH11,AM11,AR11,AW11) -> 21.75 | F11: =SUM(J11,O11,T11,Y11,AD11,AI11,AN11,AS11,AX11) -> 38.25 | G11: =SUM(K11,P11,U11,Z11,AE11,AJ11,AO11,AT11,AY11) -> 1 | H11: =SUM(L11,Q11,V11,AA11,AF11,AK11,AP11,AU11,BA11) -> 1 | I11: 6 | J11: 6 | N11: 0 | S11: 6 | T11: 6 | U11: 1 | V11: 1 | W11: LTIM yet to prepare KCD docs. | X11: =2+2 -> 4 | Y11: 4 | AC11: 0 | AD11: 16 | AG11: Document review & History tickets covered before schedule | AH11: 2.5 | AI11: 3 | AM11: 0.25 | AN11: 0.25 | AQ11: CMDB is scheduled for 4 days | AR11: 1 | AS11: 1 | AW11: 2 | AX11: 2
B12: F | C12: =C11+1 -> 45709 | D12: =IF(E12=0,0,F12/E12) -> 0.96129032 | E12: =SUM(I12,N12,S12,X12,AC12,AH12,AM12,AR12,AW12) -> 38.75 | F12: =SUM(J12,O12,T12,Y12,AD12,AI12,AN12,AS12,AX12) -> 37.25 | G12: =SUM(K12,P12,U12,Z12,AE12,AJ12,AO12,AT12,AY12) -> 1 | H12: =SUM(L12,Q12,V12,AA12,AF12,AK12,AP12,AU12,BA12) -> 0 | I12: 13 | J12: 13 | N12: 0 | P12: 0 | Q12: 0 | S12: 6 | T12: 6 | X12: =2+6 -> 8 | Y12: =2+6 -> 8 | AC12: 7 | AD12: 4 | AG12: Few points covered yesterday. Play back moced to thrusday as per LTIM request | AH12: 1.5 | AI12: 2 | AM12: 0.25 | AN12: 0.25 | AR12: 0 | AS12: 1 | AT12: 1 | AU12: 0 | AW12: 3 | AX12: 3
B13: Week Status | D13: =IF(E13=0,0,F13/E13) -> 1.2852941 | E13: =SUM(E8:E12) -> 170 | F13: =SUM(F8:F12) -> 218.5 | G13: =SUM(G8:G12) -> 2 | H13: =SUM(H8:H12) -> 1 | I13: =SUM(I8:I12) -> 44 | J13: =SUM(J8:J12) -> 44 | K13: =SUM(K8:K12) -> 0 | L13: =SUM(L8:L12) -> 0 | N13: =SUM(N8:N12) -> 0 | O13: =SUM(O8:O12) -> 0 | P13: =SUM(P8:P12) -> 0 | Q13: =SUM(Q8:Q12) -> 0 | S13: =SUM(S8:S12) -> 31 | T13: =SUM(T8:T12) -> 31 | U13: =SUM(U8:U12) -> 1 | V13: =SUM(V8:V12) -> 1 | X13: =SUM(X8:X12) -> 12 | Y13: =SUM(Y8:Y12) -> 12 | Z13: =SUM(Z8:Z12) -> 0 | AA13: =SUM(AA8:AA12) -> 0 | AC13: =SUM(AC8:AC12) -> 50 | AD13: =SUM(AD8:AD12) -> 95 | AE13: =SUM(AE8:AE12) -> 0 | AF13: =SUM(AF8:AF12) -> 0 | AH13: =SUM(AH8:AH12) -> 6.5 | AI13: =SUM(AI8:AI12) -> 9 | AJ13: =SUM(AJ8:AJ12) -> 0 | AK13: =SUM(AK8:AK12) -> 0 | AM13: =SUM(AM8:AM12) -> 7.5 | AN13: =SUM(AN8:AN12) -> 7.5 | AO13: =SUM(AO8:AO12) -> 0 | AP13: =SUM(AP8:AP12) -> 0 | AR13: =SUM(AR8:AR12) -> 4 | AS13: =SUM(AS8:AS12) -> 5 | AT13: =SUM(AT8:AT12) -> 1 | AU13: =SUM(AU8:AU12) -> 0 | AW13: =SUM(AW8:AW12) -> 15 | AX13: =SUM(AX8:AX12) -> 15 | AY13: =SUM(AY8:AY12) -> 0 | AZ13: =SUM(AZ8:AZ12) -> 0
B14: M | C14: =C12+3 -> 45712 | D14: =IF(E14=0,0,F14/E14) -> 0.97684211 | E14: =SUM(I14,N14,S14,X14,AC14,AH14,AM14,AR14,AW14) -> 118.75 | F14: =SUM(J14,O14,T14,Y14,AD14,AI14,AN14,AS14,AX14) -> 116 | G14: =SUM(K14,P14,U14,Z14,AE14,AJ14,AO14,AT14,AY14) -> 0 | H14: =SUM(L14,Q14,V14,AA14,AF14,AK14,AP14,AU14,BA14) -> 0 | I14: 33 | J14: 27 | M14: Balance KT topic will be covered in the next session as planned. | N14: 57 | O14: 57 | S14: 8 | T14: 8 | X14: =5+1+4 -> 10 | Y14: 10 | AC14: 6 | AD14: 10 | AH14: 1.5 | AI14: 2 | AM14: 0.25 | AN14: 0 | AR14: 1 | AS14: 0 | AV14: Covered KT on 21st Feb and Playback Session was not happened on 21st Feb. | AW14: 2 | AX14: 2 | BB14: 1 | BC14: 1
B15: T | C15: =C14+1 -> 45713 | D15: =IF(E15=0,0,F15/E15) -> 0.84648188 | E15: =SUM(I15,N15,S15,X15,AC15,AH15,AM15,AR15,AW15) -> 117.25 | F15: =SUM(J15,O15,T15,Y15,AD15,AI15,AN15,AS15,AX15) -> 99.25 | G15: =SUM(K15,P15,U15,Z15,AE15,AJ15,AO15,AT15,AY15) -> 1 | H15: =SUM(L15,Q15,V15,AA15,AF15,AK15,AP15,AU15,BA15) -> 1 | I15: 33 | J15: 17 | M15: Balance KT topic will be covered in the next session. One of resource is OOO from TCS till 27 due to which KT topic will be covered in next session | N15: 57 | O15: 64 | S15: 8 | T15: 8 | U15: 1 | V15: 1 | X15: =4+1+2 -> 7 | Y15: 7 | AC15: 8 | AD15: 2 | AG15: Few points covered yesterday. | AH15: 3 | AI15: 0 | AL15: Sessions are cnacelled , But sessions are covered earlier | AM15: 0.25 | AN15: 0.25 | AR15: 1 | AS15: 1 | AW15: 0 | AX15: 0 | BA15: LTIM Associate OOO till 3rd March | BB15: 1 | BC15: 1
B16: W | C16: =C15+1 -> 45714 | D16: =IF(E16=0,0,F16/E16) -> 0.62095238 | E16: =SUM(I16,N16,S16,X16,AC16,AH16,AM16,AR16,AW16) -> 131.25 | F16: =SUM(J16,O16,T16,Y16,AD16,AI16,AN16,AS16,AX16) -> 81.5 | G16: =SUM(K16,P16,U16,Z16,AE16,AJ16,AO16,AT16,AY16) -> 0 | H16: =SUM(L16,Q16,V16,AA16,AF16,AK16,AP16,AU16,BA16) -> 0 | I16: 33 | J16: 0 | M16: Due to Holiday,both LTIM & TCS associates are not available | N16: 73 | O16: 64 | S16: 4 | T16: 4 | X16: =6+3+2 -> 11 | Y16: 11 | AC16: 8 | AG16: Few points covered yesterday. | AH16: 1.25 | AI16: 1.25 | AM16: 0 | AN16: 0.25 | AR16: 1 | AS16: 1 | AW16: 0 | AX16: 0 | BA16: LTIM Associate OOO till 3rd March | BB16: 2 | BC16: 2
B17: T | C17: =C16+1 -> 45715 | D17: =IF(E17=0,0,F17/E17) -> 1.1100196 | E17: =SUM(I17,N17,S17,X17,AC17,AH17,AM17,AR17,AW17) -> 127.25 | F17: =SUM(J17,O17,T17,Y17,AD17,AI17,AN17,AS17,AX17) -> 141.25 | G17: =SUM(K17,P17,U17,Z17,AE17,AJ17,AO17,AT17,AY17) -> 0 | H17: =SUM(L17,Q17,V17,AA17,AF17,AK17,AP17,AU17,BA17) -> 2 | I17: 33 | J17: 22 | N17: 72 | O17: 98 | S17: 4 | T17: 4 | X17: =5+3+0 -> 8 | Y17: 8 | AC17: 7 | AD17: 7 | AF17: 2 | AH17: 2.25 | AI17: 1.25 | AM17: 1 | AN17: 1 | AR17: 0 | AS17: 0 | AW17: 0 | AX17: 0 | BA17: LTIM Associate OOO till 3rd March
B18: F | C18: =C17+1 -> 45716 | D18: =IF(E18=0,0,F18/E18) -> 1.3809524 | E18: =SUM(I18,N18,S18,X18,AC18,AH18,AM18,AR18,AW18) -> 99.75 | F18: =SUM(J18,O18,T18,Y18,AD18,AI18,AN18,AS18,AX18) -> 137.75 | G18: =SUM(K18,P18,U18,Z18,AE18,AJ18,AO18,AT18,AY18) -> 2 | H18: =SUM(L18,Q18,V18,AA18,AF18,AK18,AP18,AU18,BA18) -> 3 | I18: 33 | J18: 64 | N18: 37 | O18: 47 | P18: 1 | Q18: 1 | S18: 4 | T18: 4 | X18: =7+4+3 -> 14 | Y18: 14 | AC18: 10 | AD18: 6 | AF18: 1 | AH18: 1.25 | AI18: 2.25 | AM18: 0.5 | AN18: 0.5 | AR18: 0 | AS18: 0 | AT18: 1 | AU18: 1 | AW18: 0 | AX18: 0 | BA18: LTIM Associate OOO till 3rd March | BB18: 1 | BC18: 1 | BF18: Knowledge Mgmt Completed
B19: Week Status | D19: =IF(E19=0,0,F19/E19) -> 0.96886832 | E19: =SUM(E14:E18) -> 594.25 | F19: =SUM(F14:F18) -> 575.75 | G19: =SUM(G14:G18) -> 3 | H19: =SUM(H14:H18) -> 6 | I19: =SUM(I14:I18) -> 165 | J19: =SUM(J14:J18) -> 130 | K19: =SUM(K14:K18) -> 0 | L19: =SUM(L14:L18) -> 0 | N19: =SUM(N14:N18) -> 296 | O19: =SUM(O14:O18) -> 330 | P19: =SUM(P14:P18) -> 1 | Q19: =SUM(Q14:Q18) -> 1 | R19: =O19/N19 -> 1.1148649 | S19: =SUM(S14:S18) -> 28 | T19: =SUM(T14:T18) -> 28 | U19: =SUM(U14:U18) -> 1 | V19: =SUM(V14:V18) -> 1 | X19: =SUM(X14:X18) -> 50 | Y19: =SUM(Y14:Y18) -> 50 | Z19: =SUM(Z14:Z18) -> 0 | AA19: =SUM(AA14:AA18) -> 0 | AC19: =SUM(AC14:AC18) -> 39 | AD19: =SUM(AD14:AD18) -> 25 | AE19: =SUM(AE14:AE18) -> 0 | AF19: =SUM(AF14:AF18) -> 3 | AH19: =SUM(AH14:AH18) -> 9.25 | AI19: =SUM(AI14:AI18) -> 6.75 | AJ19: =SUM(AJ14:AJ18) -> 0 | AK19: =SUM(AK14:AK18) -> 0 | AM19: =SUM(AM14:AM18) -> 2 | AN19: =SUM(AN14:AN18) -> 2 | AO19: =SUM(AO14:AO18) -> 0 | AP19: =SUM(AP14:AP18) -> 0 | AR19: =SUM(AR14:AR18) -> 3 | AS19: =SUM(AS14:AS18) -> 2 | AT19: =SUM(AT14:AT18) -> 1 | AU19: =SUM(AU14:AU18) -> 1 | AW19: =SUM(AW14:AW18) -> 2 | AX19: =SUM(AX14:AX18) -> 2 | AY19: =SUM(AY14:AY18) -> 0 | AZ19: =SUM(AZ14:AZ18) -> 0 | BB19: =SUM(BB14:BB18) -> 5 | BC19: =SUM(BC14:BC18) -> 5 | BD19: =SUM(BD14:BD18) -> 0 | BE19: =SUM(BE14:BE18) -> 0
B20: M | C20: =C18+3 -> 45719 | D20: =IF(E20=0,0,F20/E20) -> 1.0213849 | E20: =SUM(I20,N20,S20,X20,AC20,AH20,AM20,AR20,AW20) -> 245.5 | F20: =SUM(J20,O20,T20,Y20,AD20,AI20,AN20,AS20,AX20) -> 250.75 | G20: =SUM(K20,P20,U20,Z20,AE20,AJ20,AO20,AT20,AY20) -> 1 | H20: =SUM(L20,Q20,V20,AA20,AF20,AK20,AP20,AU20,BA20) -> 2 | I20: 44 | J20: 68 | N20: 142 | O20: 123 | P20: 1 | Q20: 1 | S20: 6 | T20: 6 | W20: KCD Signoff pending from LTIM on SFG KCD doc yet to receive for SSP from LTIM ETA: 04-Mar | X20: =5+3+4 -> 12 | Y20: 12 | AC20: 39 | AD20: 39 | AH20: 1.25 | AI20: 1.5 | AJ20: 0 | AK20: 1 | AL20: Sessions cancelled on 25th Feb is covered today . | AM20: 0.25 | AN20: 0.25 | AR20: 1 | AS20: 1 | AW20: 0 | AX20: 0 | BA20: LTIM Associate on Sick leave | BD20: 1 | BE20: 1
B21: T | C21: =C20+1 -> 45720 | D21: =IF(E21=0,0,F21/E21) -> 1.01302 | E21: =SUM(I21,N21,S21,X21,AC21,AH21,AM21,AR21,AW21) -> 153.61 | F21: =SUM(J21,O21,T21,Y21,AD21,AI21,AN21,AS21,AX21) -> 155.61 | G21: =SUM(K21,P21,U21,Z21,AE21,AJ21,AO21,AT21,AY21) -> 2 | H21: =SUM(L21,Q21,V21,AA21,AF21,AK21,AP21,AU21,BA21) -> 2 | I21: 44 | J21: 55 | K21: 1 | L21: 1 | M21: All the back logs completed | N21: 79 | O21: 74 | S21: 5 | T21: 5 | U21: 1 | V21: 1 | W21: KCD Signoff pending from LTIM on SFG KCD doc yet to receive for SSP from LTIM ETA: 04-Mar | X21: =2+4+2 -> 8 | Y21: 8 | AC21: 12 | AD21: 8 | AG21: few topics covered in initial week | AH21: 1.36 | AI21: 1.36 | AM21: 0.25 | AN21: 0.25 | AR21: 1 | AS21: 1 | AW21: 3 | AX21: 3 | BB21: 2 | BC21: 2 | BD21: 1 | BE21: 1 | BF21: Problem Mgmt Completed. Incident & KM Playback Session Done
B22: W | C22: =C21+1 -> 45721 | D22: =IF(E22=0,0,F22/E22) -> 1.006652 | E22: =SUM(I22,N22,S22,X22,AC22,AH22,AM22,AR22,AW22) -> 150.33 | F22: =SUM(J22,O22,T22,Y22,AD22,AI22,AN22,AS22,AX22) -> 151.33 | G22: =SUM(K22,P22,U22,Z22,AE22,AJ22,AO22,AT22,AY22) -> 0 | H22: =SUM(L22,Q22,V22,AA22,AF22,AK22,AP22,AU22,BA22) -> 0 | I22: 44 | J22: 44 | N22: 73 | O22: 74 | S22: 7 | T22: 7 | W22: KCD Signoff pending from LTIM on SFG KCD doc yet to receive for SSP from LTIM ETA: 04-Mar | X22: =2+4+1 -> 7 | Y22: 7 | AC22: 10 | AD22: 9 | AH22: 3.33 | AI22: 4.33 | AM22: 1 | AN22: 1 | AR22: 1 | AS22: 1 | AW22: 4 | AX22: 4 | BB22: 1 | BC22: 1
B23: T | C23: =C22+1 -> 45722 | D23: =IF(E23=0,0,F23/E23) -> 1.2982226 | E23: =SUM(I23,N23,S23,X23,AC23,AH23,AM23,AR23,AW23) -> 83.83 | F23: =SUM(J23,O23,T23,Y23,AD23,AI23,AN23,AS23,AX23) -> 108.83 | G23: =SUM(K23,P23,U23,Z23,AE23,AJ23,AO23,AT23,AY23) -> 3 | H23: =SUM(L23,Q23,V23,AA23,AF23,AK23,AP23,AU23,BA23) -> 2 | I23: 44 | J23: 44 | K23: 1 | L23: 1 | N23: 14 | O23: 42 | S23: 9 | T23: 9 | W23: KCD Signoff pending from LTIM on SFG KCD doc yet to receive for SSP from LTIM ETA: 04-Mar | X23: =2+0+2 -> 4 | Y23: 4 | Z23: 1 | AA23: 1 | AC23: 8 | AD23: 4 | AG23: Topics duration was more | AH23: 0.33 | AI23: 1.33 | AJ23: 1 | AK23: 0 | AL23: Playback moved postponed to next week | AM23: 0.5 | AN23: 0.5 | AR23: 1 | AS23: 1 | AW23: 3 | AX23: 3 | BB23: 5
B24: F | C24: =C23+1 -> 45723 | D24: =IF(E24=0,0,F24/E24) -> 0 | E24: =SUM(I24,N24,S24,X24,AC24,AH24,AM24,AR24,AW24) -> 79.75 | F24: =SUM(J24,O24,T24,Y24,AD24,AI24,AN24,AS24,AX24) -> 0 | G24: =SUM(K24,P24,U24,Z24,AE24,AJ24,AO24,AT24,AY24) -> 6 | H24: =SUM(L24,Q24,V24,AA24,AF24,AK24,AP24,AU24,BA24) -> 0 | I24: 44 | N24: 12 | P24: 2 | S24: 7 | U24: 1 | X24: =1+0+0 -> 1 | AC24: 13 | AH24: 0.25 | AJ24: 1 | AM24: 0.5 | AT24: 1 | AW24: 2 | AY24: 1
B25: Week Status | D25: =IF(E25=0,0,F25/E25) -> 0.93478444 | E25: =SUM(E20:E24) -> 713.02 | F25: =SUM(F20:F24) -> 666.52 | G25: =SUM(G20:G24) -> 12 | H25: =SUM(H20:H24) -> 6 | I25: =SUM(I20:I24) -> 220 | J25: =SUM(J20:J24) -> 211 | K25: =SUM(K20:K24) -> 2 | L25: =SUM(L20:L24) -> 2 | N25: =SUM(N20:N24) -> 320 | O25: =SUM(O20:O24) -> 313 | P25: =SUM(P20:P24) -> 3 | Q25: =SUM(Q20:Q24) -> 1 | R25: =O25/N25 -> 0.978125 | S25: =SUM(S20:S24) -> 34 | T25: =SUM(T20:T24) -> 27 | U25: =SUM(U20:U24) -> 2 | V25: =SUM(V20:V24) -> 1 | X25: =SUM(X20:X24) -> 32 | Y25: =SUM(Y20:Y24) -> 31 | Z25: =SUM(Z20:Z24) -> 1 | AA25: =SUM(AA20:AA24) -> 1 | AC25: =SUM(AC20:AC24) -> 82 | AD25: =SUM(AD20:AD24) -> 60 | AE25: =SUM(AE20:AE24) -> 0 | AF25: =SUM(AF20:AF24) -> 0 | AH25: =SUM(AH20:AH24) -> 6.52 | AI25: =SUM(AI20:AI24) -> 8.52 | AJ25: =SUM(AJ20:AJ24) -> 2 | AK25: =SUM(AK20:AK24) -> 1 | AM25: =SUM(AM20:AM24) -> 2.5 | AN25: =SUM(AN20:AN24) -> 2 | AO25: =SUM(AO20:AO24) -> 0 | AP25: =SUM(AP20:AP24) -> 0 | AR25: =SUM(AR20:AR24) -> 4 | AS25: =SUM(AS20:AS24) -> 4 | AT25: =SUM(AT20:AT24) -> 1 | AU25: =SUM(AU20:AU24) -> 0 | AW25: =SUM(AW20:AW24) -> 12 | AX25: =SUM(AX20:AX24) -> 10 | AY25: =SUM(AY20:AY24) -> 1 | AZ25: =SUM(AZ20:AZ24) -> 0 | BB25: =SUM(BB20:BB24) -> 8 | BC25: =SUM(BC20:BC24) -> 3 | BD25: =SUM(BD20:BD24) -> 2 | BE25: =SUM(BE20:BE24) -> 2
B26: M | C26: =C24+3 -> 45726 | D26: =IF(E26=0,0,F26/E26) -> 0 | E26: =SUM(I26,N26,S26,X26,AC26,AH26,AM26,AR26,AW26) -> 111.75 | F26: =SUM(J26,O26,T26,Y26,AD26,AI26,AN26,AS26,AX26) -> 0 | G26: =SUM(K26,P26,U26,Z26,AE26,AJ26,AO26,AT26,AY26) -> 1 | H26: =SUM(L26,Q26,V26,AA26,AF26,AK26,AP26,AU26,BA26) -> 0 | I26: 33 | N26: 51 | P26: 1 | S26: 4 | AC26: 20 | AH26: 1.25 | AM26: 0.5 | AW26: 2
B27: T | C27: =C26+1 -> 45727 | D27: =IF(E27=0,0,F27/E27) -> 0 | E27: =SUM(I27,N27,S27,X27,AC27,AH27,AM27,AR27,AW27) -> 97.75 | F27: =SUM(J27,O27,T27,Y27,AD27,AI27,AN27,AS27,AX27) -> 0 | G27: =SUM(K27,P27,U27,Z27,AE27,AJ27,AO27,AT27,AY27) -> 0 | H27: =SUM(L27,Q27,V27,AA27,AF27,AK27,AP27,AU27,BA27) -> 0 | I27: 33 | N27: 44 | S27: 2 | AC27: 13 | AH27: 1.25 | AM27: 0.5 | AW27: 4 | BB27: 0
B28: W | C28: =C27+1 -> 45728 | D28: =IF(E28=0,0,F28/E28) -> 0 | E28: =SUM(I28,N28,S28,X28,AC28,AH28,AM28,AR28,AW28) -> 96.25 | F28: =SUM(J28,O28,T28,Y28,AD28,AI28,AN28,AS28,AX28) -> 0 | G28: =SUM(K28,P28,U28,Z28,AE28,AJ28,AO28,AT28,AY28) -> 0 | H28: =SUM(L28,Q28,V28,AA28,AF28,AK28,AP28,AU28,BA28) -> 0 | I28: 22 | N28: 52 | S28: 3 | AC28: 12 | AH28: 1.25 | AM28: 2 | AW28: 4
B29: T | C29: =C28+1 -> 45729 | D29: =IF(E29=0,0,F29/E29) -> 0 | E29: =SUM(I29,N29,S29,X29,AC29,AH29,AM29,AR29,AW29) -> 113.14 | F29: =SUM(J29,O29,T29,Y29,AD29,AI29,AN29,AS29,AX29) -> 0 | G29: =SUM(K29,P29,U29,Z29,AE29,AJ29,AO29,AT29,AY29) -> 1 | H29: =SUM(L29,Q29,V29,AA29,AF29,AK29,AP29,AU29,BA29) -> 0 | I29: 22 | N29: 70 | S29: 2 | AC29: 11 | AH29: 1.14 | AM29: 3 | AT29: 1 | AW29: 4
B30: F | C30: =C29+1 -> 45730 | D30: =IF(E30=0,0,F30/E30) -> 0 | E30: =SUM(I30,N30,S30,X30,AC30,AH30,AM30,AR30,AW30) -> 63.14 | F30: =SUM(J30,O30,T30,Y30,AD30,AI30,AN30,AS30,AX30) -> 0 | G30: =SUM(K30,P30,U30,Z30,AE30,AJ30,AO30,AT30,AY30) -> 3 | H30: =SUM(L30,Q30,V30,AA30,AF30,AK30,AP30,AU30,BA30) -> 0 | I30: 22 | N30: 17 | P30: 1 | S30: 1 | AC30: 8 | AH30: 1.14 | AM30: 10 | AO30: 1 | AT30: 1 | AW30: 4
B31: Week Status | D31: =IF(E31=0,0,F31/E31) -> 0 | E31: =SUM(E26:E30) -> 482.03 | F31: =SUM(F26:F30) -> 0 | G31: =SUM(G26:G30) -> 5 | H31: =SUM(H26:H30) -> 0 | I31: =SUM(I26:I30) -> 132 | J31: =SUM(J26:J30) -> 0 | K31: =SUM(K26:K30) -> 0 | L31: =SUM(L26:L30) -> 0 | N31: =SUM(N26:N30) -> 234 | O31: =SUM(O26:O30) -> 0 | P31: =SUM(P26:P30) -> 2 | Q31: =SUM(Q26:Q30) -> 0 | S31: =SUM(S26:S30) -> 12 | T31: =SUM(T26:T30) -> 0 | U31: =SUM(U26:U30) -> 0 | V31: =SUM(V26:V30) -> 0 | X31: =SUM(X26:X30) -> 0 | Y31: =SUM(Y26:Y30) -> 0 | Z31: =SUM(Z26:Z30) -> 0 | AA31: =SUM(AA26:AA30) -> 0 | AC31: =SUM(AC26:AC30) -> 64 | AD31: =SUM(AD26:AD30) -> 0 | AE31: =SUM(AE26:AE30) -> 0 | AF31: =SUM(AF26:AF30) -> 0 | AH31: =SUM(AH26:AH30) -> 6.03 | AI31: =SUM(AI26:AI30) -> 0 | AJ31: =SUM(AJ26:AJ30) -> 0 | AK31: =SUM(AK26:AK30) -> 0 | AM31: =SUM(AM26:AM30) -> 16 | AN31: =SUM(AN26:AN30) -> 0 | AO31: =SUM(AO26:AO30) -> 1 | AP31: =SUM(AP26:AP30) -> 0 | AR31: =SUM(AR26:AR30) -> 0 | AS31: =SUM(AS26:AS30) -> 0 | AT31: =SUM(AT26:AT30) -> 2 | AU31: =SUM(AU26:AU30) -> 0 | AW31: =SUM(AW26:AW30) -> 18 | AX31: =SUM(AX26:AX30) -> 0 | AY31: =SUM(AY26:AY30) -> 0 | AZ31: =SUM(AZ26:AZ30) -> 0
B32: M | C32: =C30+3 -> 45733 | D32: =IF(E32=0,0,F32/E32) -> 0 | E32: =SUM(I32,N32,S32,X32,AC32,AH32,AM32,AR32,AW32) -> 91.14 | F32: =SUM(J32,O32,T32,Y32,AD32,AI32,AN32,AS32,AX32) -> 0 | G32: =SUM(K32,P32,U32,Z32,AE32,AJ32,AO32,AT32,AY32) -> 1 | H32: =SUM(L32,Q32,V32,AA32,AF32,AK32,AP32,AU32,BA32) -> 0 | I32: 11 | N32: 61 | P32: 1 | S32: 3 | AC32: 11 | AH32: 1.14 | AQ32: SECONDARY SUPPORT | AV32: SECONDARY SUPPORT | AW32: 4
B33: T | C33: =C32+1 -> 45734 | D33: =IF(E33=0,0,F33/E33) -> 0 | E33: =SUM(I33,N33,S33,X33,AC33,AH33,AM33,AR33,AW33) -> 138.14 | F33: =SUM(J33,O33,T33,Y33,AD33,AI33,AN33,AS33,AX33) -> 0 | G33: =SUM(K33,P33,U33,Z33,AE33,AJ33,AO33,AT33,AY33) -> 0 | H33: =SUM(L33,Q33,V33,AA33,AF33,AK33,AP33,AU33,BA33) -> 0 | I33: 11 | N33: 107 | S33: 3 | AC33: 13 | AH33: 0.14 | AW33: 4
B34: W | C34: =C33+1 -> 45735 | D34: =IF(E34=0,0,F34/E34) -> 0 | E34: =SUM(I34,N34,S34,X34,AC34,AH34,AM34,AR34,AW34) -> 91.14 | F34: =SUM(J34,O34,T34,Y34,AD34,AI34,AN34,AS34,AX34) -> 0 | G34: =SUM(K34,P34,U34,Z34,AE34,AJ34,AO34,AT34,AY34) -> 0 | H34: =SUM(L34,Q34,V34,AA34,AF34,AK34,AP34,AU34,BA34) -> 0 | I34: 11 | N34: 44 | S34: 2 | AC34: 32 | AH34: 0.14 | AW34: 2
B35: T | C35: =C34+1 -> 45736 | D35: =IF(E35=0,0,F35/E35) -> 0 | E35: =SUM(I35,N35,S35,X35,AC35,AH35,AM35,AR35,AW35) -> 60.14 | F35: =SUM(J35,O35,T35,Y35,AD35,AI35,AN35,AS35,AX35) -> 0 | G35: =SUM(K35,P35,U35,Z35,AE35,AJ35,AO35,AT35,AY35) -> 1 | H35: =SUM(L35,Q35,V35,AA35,AF35,AK35,AP35,AU35,BA35) -> 0 | I35: 11 | N35: 17 | P35: 1 | S35: 2 | AC35: 25 | AH35: 1.14 | AW35: 4
B36: F | C36: =C35+1 -> 45737 | D36: =IF(E36=0,0,F36/E36) -> 0 | E36: =SUM(I36,N36,S36,X36,AC36,AH36,AM36,AR36,AW36) -> 98.14 | F36: =SUM(J36,O36,T36,Y36,AD36,AI36,AN36,AS36,AX36) -> 0 | G36: =SUM(K36,P36,U36,Z36,AE36,AJ36,AO36,AT36,AY36) -> 1 | H36: =SUM(L36,Q36,V36,AA36,AF36,AK36,AP36,AU36,BA36) -> 0 | I36: 11 | N36: 56 | S36: 3 | AC36: 24 | AH36: 0.14 | AW36: 4 | AY36: 1
B37: Week Status | D37: =IF(E37=0,0,F37/E37) -> 0 | E37: =SUM(E32:E36) -> 478.7 | F37: =SUM(F32:F36) -> 0 | G37: =SUM(G32:G36) -> 3 | H37: =SUM(H32:H36) -> 0 | I37: =SUM(I32:I36) -> 55 | J37: =SUM(J32:J36) -> 0 | K37: =SUM(K32:K36) -> 0 | L37: =SUM(L32:L36) -> 0 | N37: =SUM(N32:N36) -> 285 | O37: =SUM(O32:O36) -> 0 | P37: =SUM(P32:P36) -> 2 | Q37: =SUM(Q32:Q36) -> 0 | S37: =SUM(S32:S36) -> 13 | T37: =SUM(T32:T36) -> 0 | U37: =SUM(U32:U36) -> 0 | V37: =SUM(V32:V36) -> 0 | X37: =SUM(X32:X36) -> 0 | Y37: =SUM(Y32:Y36) -> 0 | Z37: =SUM(Z32:Z36) -> 0 | AA37: =SUM(AA32:AA36) -> 0 | AC37: =SUM(AC32:AC36) -> 105 | AD37: =SUM(AD32:AD36) -> 0 | AE37: =SUM(AE32:AE36) -> 0 | AF37: =SUM(AF32:AF36) -> 0 | AG37: 14 Topics + 2 Play back were tagged to weekend. Move to weekdays | AH37: =SUM(AH32:AH36) -> 2.7 | AI37: =SUM(AI32:AI36) -> 0 | AJ37: =SUM(AJ32:AJ36) -> 0 | AK37: =SUM(AK32:AK36) -> 0 | AW37: =SUM(AW32:AW36) -> 18 | AX37: =SUM(AX32:AX36) -> 0 | AY37: =SUM(AY32:AY36) -> 1 | AZ37: =SUM(AZ32:AZ36) -> 0
B38: M | C38: =C36+3 -> 45740 | D38: =IF(E38=0,0,F38/E38) -> 0 | E38: =SUM(I38,N38,S38,X38,AC38,AH38,AM38,AR38,AW38) -> 64 | F38: =SUM(J38,O38,T38,Y38,AD38,AI38,AN38,AS38,AX38) -> 0 | G38: =SUM(K38,P38,U38,Z38,AE38,AJ38,AO38,AT38,AY38) -> 7 | H38: =SUM(L38,Q38,V38,AA38,AF38,AK38,AP38,AU38,BA38) -> 0 | I38: 11 | N38: 28 | P38: 1 | S38: 3 | AC38: 17 | AE38: 6 | AH38: 1 | AW38: 4
B39: T | C39: =C38+1 -> 45741 | D39: =IF(E39=0,0,F39/E39) -> 0 | E39: =SUM(I39,N39,S39,X39,AC39,AH39,AM39,AR39,AW39) -> 50.25 | F39: =SUM(J39,O39,T39,Y39,AD39,AI39,AN39,AS39,AX39) -> 0 | G39: =SUM(K39,P39,U39,Z39,AE39,AJ39,AO39,AT39,AY39) -> 1 | H39: =SUM(L39,Q39,V39,AA39,AF39,AK39,AP39,AU39,BA39) -> 0 | I39: 11 | N39: 27 | S39: 3 | AC39: 5 | AE39: 1 | AH39: 0.25 | AW39: 4
B40: W | C40: =C39+1 -> 45742 | D40: =IF(E40=0,0,F40/E40) -> 0 | E40: =SUM(I40,N40,S40,X40,AC40,AH40,AM40,AR40,AW40) -> 51.25 | F40: =SUM(J40,O40,T40,Y40,AD40,AI40,AN40,AS40,AX40) -> 0 | G40: =SUM(K40,P40,U40,Z40,AE40,AJ40,AO40,AT40,AY40) -> 2 | H40: =SUM(L40,Q40,V40,AA40,AF40,AK40,AP40,AU40,BA40) -> 0 | I40: 11 | N40: 31 | S40: 5 | AC40: 2 | AE40: 1 | AH40: 0.25 | AJ40: 1 | AW40: 2
B41: T | C41: =C40+1 -> 45743 | D41: =IF(E41=0,0,F41/E41) -> 0 | E41: =SUM(I41,N41,S41,X41,AC41,AH41,AM41,AR41,AW41) -> 73.25 | F41: =SUM(J41,O41,T41,Y41,AD41,AI41,AN41,AS41,AX41) -> 0 | G41: =SUM(K41,P41,U41,Z41,AE41,AJ41,AO41,AT41,AY41) -> 1 | H41: =SUM(L41,Q41,V41,AA41,AF41,AK41,AP41,AU41,BA41) -> 0 | I41: 11 | N41: 57 | S41: 3 | AH41: 0.25 | AJ41: 1 | AW41: 2
B42: F | C42: =C41+1 -> 45744 | D42: =IF(E42=0,0,F42/E42) -> 0 | E42: =SUM(I42,N42,S42,X42,AC42,AH42,AM42,AR42,AW42) -> 50.25 | F42: =SUM(J42,O42,T42,Y42,AD42,AI42,AN42,AS42,AX42) -> 0 | G42: =SUM(K42,P42,U42,Z42,AE42,AJ42,AO42,AT42,AY42) -> 2 | H42: =SUM(L42,Q42,V42,AA42,AF42,AK42,AP42,AU42,BA42) -> 0 | I42: 11 | N42: 31 | S42: 6 | U42: 1 | AH42: 1.25 | AJ42: 1 | AW42: 1
...

Sheet Detailed New
D2: TCS Transition Dashboard
B4: All Tower Combined Status | I4: Corp Apps | N4: SAP | S4: Integration | X4: EIT | AC4: EDA | AH4: SharePoint | AM4: SNOW | AR4: LAN | AW4: AS400 | BB4: SIAM
I5: KT (P) Till today | J5: KT (A) Till today | K5: PlayBack (P) | L5: PlayBack (A) | M5: KT till today % | N5: KT (P) Till today | O5: KT (A) Till today | P5: PlayBack (P) | Q5: PlayBack (A) | R5: KT till today % | S5: KT (P) Till today | T5: KT (A) Till today | U5: PlayBack (P) | V5: PlayBack (A) | W5: KT till today % | X5: KT (P) Till today | Y5: KT (A) Till today | Z5: PlayBack (P) | AA5: PlayBack (A) | AB5: KT till today % | AC5: KT (P) Till today | AD5: KT (A) Till today | AE5: PlayBack (P) | AF5: PlayBack (A) | AG5: KT till today % | AH5: KT (P) Till today | AI5: KT (A) Till today | AJ5: PlayBack (P) | AK5: PlayBack (A) | AL5: KT till today % | AM5: KT (P) Till today | AN5: KT (A) Till today | AO5: PlayBack (P) | AP5: PlayBack (A) | AQ5: KT till today % | AR5: KT (P) Till today | AS5: KT (A) Till today | AT5: PlayBack (P) | AU5: PlayBack (A) | AV5: KT till today % | AW5: KT (P) Till today | AX5: KT (A) Till today | AY5: PlayBack (P) | AZ5: PlayBack (A) | BA5: KT till today % | BB5: KT (P) Till today | BC5: KT (A) Till today | BD5: PlayBack (P) | BE5: PlayBack (A) | BF5: KT till today %
I6: =SUMIF($C$9:$C$71,"<"&"="&TODAY(),I9:I71) -> 660 | J6: =SUMIF($C$9:$C$71,"<"&"="&TODAY(),J9:J71) -> 660 | K6: =SUMIF($C$9:$C$71,"<"&"="&TODAY(),K9:K71) -> 36 | L6: =SUMIF($C$9:$C$71,"<"&"="&TODAY(),L9:L71) -> 34 | M6: =J6/I6 -> 1 | N6: =SUMIF($C$9:$C$71,"<"&"="&TODAY(),N9:N71) -> 1296 | O6: =SUMIF($C$9:$C$71,"<"&"="&TODAY(),O9:O71) -> 1295 | P6: =SUMIF($C$9:$C$71,"<"&"="&TODAY(),P9:P71) -> 18 | Q6: =SUMIF($C$9:$C$71,"<"&"="&TODAY(),Q9:Q71) -> 18 | R6: =O6/N6 -> 0.9992284 | S6: =SUMIF($C$9:$C$71,"<"&"="&TODAY(),S9:S71) -> 131 | T6: =SUMIF($C$9:$C$71,"<"&"="&TODAY(),T9:T71) -> 131 | U6: =SUMIF($C$9:$C$71,"<"&"="&TODAY(),U9:U71) -> 6 | V6: =SUMIF($C$9:$C$71,"<"&"="&TODAY(),V9:V71) -> 6 | W6: =T6/S6 -> 1 | X6: =SUMIF($C$9:$C$71,"<"&"="&TODAY(),X9:X71) -> 348 | Y6: =SUMIF($C$9:$C$71,"<"&"="&TODAY(),Y9:Y71) -> 348 | Z6: =SUMIF($C$9:$C$71,"<"&"="&TODAY(),Z9:Z71) -> 12 | AA6: =SUMIF($C$9:$C$71,"<"&"="&TODAY(),AA9:AA71) -> 13 | AB6: =Y6/X6 -> 1 | AC6: =SUMIF($C$9:$C$71,"<"&"="&TODAY(),AC9:AC71) -> 348 | AD6: =SUMIF($C$9:$C$71,"<"&"="&TODAY(),AD9:AD71) -> 348 | AE6: =SUMIF($C$9:$C$71,"<"&"="&TODAY(),AE9:AE71) -> 8 | AF6: =SUMIF($C$9:$C$71,"<"&"="&TODAY(),AF9:AF71) -> 8 | AG6: =AD6/AC6 -> 1 | AH6: =SUMIF($C$9:$C$71,"<"&"="&TODAY(),AH9:AH71) -> 35 | AI6: =SUMIF($C$9:$C$71,"<"&"="&TODAY(),AI9:AI71) -> 35 | AJ6: =SUMIF($C$9:$C$71,"<"&"="&TODAY(),AJ9:AJ71) -> 11 | AK6: =SUMIF($C$9:$C$71,"<"&"="&TODAY(),AK9:AK71) -> 13 | AL6: =AI6/AH6 -> 1 | AM6: =SUMIF($C$9:$C$71,"<"&"="&TODAY(),AM9:AM71) -> 28 | AN6: =SUMIF($C$9:$C$71,"<"&"="&TODAY(),AN9:AN71) -> 28 | AO6: =SUMIF($C$9:$C$71,"<"&"="&TODAY(),AO9:AO71) -> 2 | AP6: =SUMIF($C$9:$C$71,"<"&"="&TODAY(),AP9:AP71) -> 2 | AQ6: =AN6/AM6 -> 1 | AR6: =SUMIF($C$9:$C$71,"<"&"="&TODAY(),AR9:AR71) -> 11 | AS6: =SUMIF($C$9:$C$71,"<"&"="&TODAY(),AS9:AS71) -> 12 | AT6: =SUMIF($C$9:$C$71,"<"&"="&TODAY(),AT9:AT71) -> 5 | AU6: =SUMIF($C$9:$C$71,"<"&"="&TODAY(),AU9:AU71) -> 4 | AV6: =AS6/AR6 -> 1.0909091 | AW6: =SUMIF($C$9:$C$71,"<"&"="&TODAY(),AW9:AW71) -> 88 | AX6: =SUMIF($C$9:$C$71,"<"&"="&TODAY(),AX9:AX71) -> 88 | AY6: =SUMIF($C$9:$C$71,"<"&"="&TODAY(),AY9:AY71) -> 2 | AZ6: =SUMIF($C$9:$C$71,"<"&"="&TODAY(),AZ9:AZ71) -> 2 | BA6: =AX6/AW6 -> 1 | BB6: =SUMIF($C$9:$C$71,"<"&"="&TODAY(),BB9:BB71) -> 19 | BC6: =SUMIF($C$9:$C$71,"<"&"="&TODAY(),BC9:BC71) -> 19 | BD6: =SUMIF($C$9:$C$71,"<"&"="&TODAY(),BD9:BD71) -> 19 | BE6: =SUMIF($C$9:$C$71,"<"&"="&TODAY(),BE9:BE71) -> 19 | BF6: =BC6/BB6 -> 1
B7: KT Topics | D7: Overall | E7: Planned | F7: Actual | G7: Playback (P) | H7: Playback (A) | I7: Planned | J7: Actual | K7: Playback (P) | L7: Playback (A) | M7: Notes | N7: Planned | O7: Actual | P7: Playback (P) | Q7: Playback (A) | R7: Notes | S7: Planned | T7: Actual | U7: Playback (P) | V7: Playback (A) | W7: Notes | X7: Planned | Y7: Actual | Z7: Playback (P) | AA7: Playback (A) | AB7: Notes | AC7: Planned | AD7: Actual | AE7: Playback (P) | AF7: Playback (A) | AG7: Notes | AH7: Planned | AI7: Actual | AJ7: Playback (P) | AK7: Playback (A) | AL7: Notes | AM7: Planned | AN7: Actual | AO7: Playback (P) | AP7: Playback (A) | AQ7: Notes | AR7: Planned | AS7: Actual | AT7: Playback (P) | AU7: Playback (A) | AV7: Notes | AW7: Planned | AX7: Actual | AY7: Playback (P) | AZ7: Playback (A) | BA7: Notes | BB7: Planned | BC7: Actual | BD7: Playback (P) | BE7: Playback (A) | BF7: Notes
